Workbook

Sheet guide
A1: 품목코드(이카운트) | B1: 바코드(SKU) | C1: 바코드(중포) | D1: 바코드(카톤) | E1: 품목명(이카운트) | F1: 상태 | G1: 판매처 | H1: 판매처관리코드 | I1: 판매처 품목명 | J1: 규격 | K1: 구매처 | L1: 수급형태 | M1: 발주부서 | N1: 발주담당자 | O1: 구매처 품목코드 | P1: 구매처 품목명 | Q1: 창고그룹(이카운트) | R1: 사용창고 | S1: 구분 | T1: 카테고리
A2: daiso1012146 | B2: 8819910121468 | C2: 28819910121462 | D2: 38819910121469 | E2: 1012146/낫 18CM | F2: 판매중 | G2: 다이소 | H2: 1012146 | I2: =VLOOKUP(A:A,[1]기본데이터!$B:$E,4,0) -> 낫 (18 cm) | J2: 18.5cm | K2: NINGBO SOURCE E-BUSINESS CO., LTD | L2: 무역(수입) | M2: 글로벌소싱부 | Q2: 유통사업부 | R2: 툴스피아,우리물류(회송전) | S2: [상품] | T2: 원예
A3: daiso1015891 | D3: 0 | E3: 1015891/다용도 커터[단종] | F3: 단종 | G3: 다이소 | J3: 169mm | L3: 무역(수입) | M3: 글로벌소싱부 | Q3: 유통사업부 | R3: 툴스피아,우리물류(회송전) | S3: [상품] | T3: 공구
A4: daiso1015892 | B4: 8819910158921 | C4: 28819910158925 | D4: 38819910158922 | E4: 1015892/칼+날2P | F4: 판매중 | G4: 다이소 | H4: 1015892 | I4: =VLOOKUP(A:A,[1]기본데이터!$B:$E,4,0) -> 칼+날2P | J4: 121mm | K4: XT-HENAN JUSEN MEASURING TOOLS CO., LTD | L4: 무역(수입) | M4: 글로벌소싱부 | Q4: 유통사업부 | R4: 툴스피아,우리물류(회송전) | S4: [상품] | T4: 공구
A5: daiso1019757 | B5: 8819910197579 | C5: 28819910197573 | D5: 38819910197570 | E5: 1019757/양용타격드라이버 | F5: 판매중 | G5: 다이소 | H5: 1019757 | I5: =VLOOKUP(A:A,[1]기본데이터!$B:$E,4,0) -> 양용타격드라이버 | K5: SHANGQIU KEMING INDUSTRIAL AND MEASURING TOOLS CO. | L5: 무역(수입) | M5: 글로벌소싱부 | Q5: 유통사업부 | R5: 툴스피아,우리물류(회송전) | S5: [상품] | T5: 공구
A6: daiso1019758 | D6: 38819910197587 | E6: 1019758/산업용커터칼세트(리필칼날10p) | F6: 단종 | G6: 다이소 | H6: 1019758 | I6: =VLOOKUP(A:A,[1]기본데이터!$B:$E,4,0) -> 단종 | J6: 칼165mm/칼날18mm | K6: XT-HENAN JUSEN MEASURING TOOLS CO., LTD | L6: 무역(수입) | M6: 글로벌소싱부 | Q6: 유통사업부 | R6: 툴스피아,우리물류(회송전) | S6: [상품] | T6: 공구
A7: daiso1019759 | B7: 8819910197593 | C7: 28819910197597 | D7: 38819910197594 | E7: 1019759/메탈샤워호스4M | F7: 판매중 | G7: 다이소 | H7: 1019759 | I7: =VLOOKUP(A:A,[1]기본데이터!$B:$E,4,0) -> 메탈 샤워호스 (4 m) | J7: 4m | K7: NINGBO SOURCE E-BUSINESS CO., LTD | L7: 무역(수입) | M7: 글로벌소싱부 | Q7: 유통사업부 | R7: 툴스피아,우리물류(회송전) | S7: [상품] | T7: 수전
A8: daiso1021017 | D8: 38819910210170 | E8: 1021017/줄자20M | F8: 단종 | G8: 다이소 | H8: 1021017 | J8: 20m*12mm | K8: XT-HENAN JUSEN MEASURING TOOLS CO., LTD | L8: 무역(수입) | M8: 글로벌소싱부 | Q8: 유통사업부 | R8: 툴스피아,우리물류(회송전) | S8: [상품] | T8: 공구
A9: daiso1024356 | B9: 8819910243566 | C9: 28819910243560 | D9: 38819910243567 | E9: 1024356/필터정수샤워기 | F9: 판매중 | G9: 다이소 | H9: 1024356 | I9: =VLOOKUP(A:A,[1]기본데이터!$B:$E,4,0) -> 필터정수 샤워기 | J9: 80*260mm(필터,세라믹볼,필터시트) | K9: NINGBO ZEXIN SANITARY WARE CO., LTD | L9: 무역(수입) | M9: 글로벌소싱부 | Q9: 유통사업부 | R9: 툴스피아,우리물류(회송전) | S9: [상품] | T9: 필터
A10: daiso1024367 | B10: 8819910243672 | C10: 28819910243676 | D10: 38819910243673 | E10: 1024367/2단계필터샤워기 | F10: 판매중 | G10: 다이소 | H10: 1024367 | I10: =VLOOKUP(A:A,[1]기본데이터!$B:$E,4,0) -> 2단계 필터샤워기 | J10: 80*260mm | K10: NINGBO SMARTLIFE HOURSEWARE PRODUCTS CO., LTD | L10: 무역(수입) | M10: 글로벌소싱부 | Q10: 유통사업부 | R10: 툴스피아,우리물류(회송전) | S10: [상품] | T10: 필터
A11: daiso1024369 | B11: 8819910243696 | C11: 28819910243690 | D11: 38819910243697 | E11: 1024369/필터샤워기리필3p | F11: 판매중 | G11: 다이소 | H11: 1024369 | I11: =VLOOKUP(A:A,[1]기본데이터!$B:$E,4,0) -> 필터 샤워기 리필3P | J11: 3p | K11: 외주포장 | Q11: 유통사업부 | R11: 툴스피아,우리물류(회송전) | S11: [상품] | T11: 필조
A12: daiso1024369-1 | E12: 1024369/필터샤워기리필 조립 | F12: 기타 | G12: 다이소 | K12: 외주포장 | Q12: 유통사업부 | R12: 툴스피아,우리물류(회송전) | S12: [반제품] | T12: 필조
A13: daiso1026718 | B13: 8819910267180 | C13: 28819910267184 | D13: 38819910267181 | E13: 1026718/비타민샤워필터(레몬) | F13: 판매중 | G13: 다이소 | H13: 1026718 | I13: =VLOOKUP(A:A,[1]기본데이터!$B:$E,4,0) -> 비타민 샤워필터(레몬) | J13: 4*14*3*0,145g | K13: (주)마오테크놀러지 | L13: 국내사입 | M13: 물류운영부 | N13: 박유정 | Q13: 유통사업부 | R13: 툴스피아,우리물류(회송전) | S13: [상품] | T13: 필터
A14: daiso1026727 | B14: 8819910267272 | C14: 28819910267276 | D14: 38819910267273 | E14: 1026727/비타민샤워필터(체리블라썸) | F14: 판매중 | G14: 다이소 | H14: 1026727 | I14: =VLOOKUP(A:A,[1]기본데이터!$B:$E,4,0) -> 비타민 샤워필터(체리블라썸) | J14: 4*14*3*0,145g | K14: (주)마오테크놀러지 | L14: 국내사입 | M14: 물류운영부 | N14: 박유정 | Q14: 유통사업부 | R14: 툴스피아,우리물류(회송전) | S14: [상품] | T14: 필터
A15: daiso1026728 | B15: 8819910267289 | C15: 28819910267283 | D15: 38819910267280 | E15: 1026728/비타민샤워필터(라벤더) | F15: 판매중 | G15: 다이소 | H15: 1026728 | I15: =VLOOKUP(A:A,[1]기본데이터!$B:$E,4,0) -> 비타민 샤워필터(라벤다) | J15: 4*14*3*0,145g | K15: (주)마오테크놀러지 | L15: 국내사입 | M15: 물류운영부 | N15: 박유정 | Q15: 유통사업부 | R15: 툴스피아,우리물류(회송전) | S15: [상품] | T15: 필터
A16: daiso1029132 | B16: 8819910291321 | C16: 28819910291325 | D16: 38819910291322 | E16: 1029132/싱크대용 필터헤드(핸디형) | F16: 판매중 | G16: 다이소 | H16: 1029132 | I16: =VLOOKUP(A:A,[1]기본데이터!$B:$E,4,0) -> 싱크대용 필터헤드(핸디형) | J16: 18*8*6 | K16: NINGBO ZEXIN SANITARY WARE CO., LTD | L16: 무역(수입) | M16: 글로벌소싱부 | Q16: 유통사업부 | R16: 툴스피아,우리물류(회송전) | S16: [상품] | T16: 수전
A17: daiso1029133 | B17: 8819910291338 | C17: 28819910291332 | D17: 38819910291339 | E17: 1029133/싱크대용리필필터(4개입) | F17: 판매중 | G17: 다이소 | H17: 1029133 | I17: =VLOOKUP(A:A,[1]기본데이터!$B:$E,4,0) -> 싱크대용리필필터(4개입) | J17: 6*2*1 | K17: NINGBO SOURCE E-BUSINESS CO., LTD | L17: 무역(수입) | M17: 글로벌소싱부 | Q17: 유통사업부 | R17: 툴스피아,우리물류(회송전) | S17: [상품] | T17: 필조
A18: daiso1029133-1 | E18: 1029133/싱크대용리필필터(4개입)_인터넷판매 | F18: 기타 | G18: 다이소 | J18: 6*2*1 | K18: NINGBO SOURCE E-BUSINESS CO., LTD | L18: 무역(수입) | M18: 글로벌소싱부 | Q18: 유통사업부 | R18: 툴스피아,우리물류(회송전) | S18: [상품] | T18: 필조
A19: daiso1029134 | B19: 8819910291345 | C19: 28819910291349 | D19: 38819910291346 | E19: 1029134/녹물차단 필터 | F19: 판매중 | G19: 다이소 | H19: 1029134 | I19: =VLOOKUP(A:A,[1]기본데이터!$B:$E,4,0) -> 녹물차단 필터 | J19: 5*14*3*0 | K19: (주)마오테크놀러지 | L19: 국내사입 | M19: 물류운영부 | N19: 박유정 | Q19: 유통사업부 | R19: 툴스피아,우리물류(회송전) | S19: [상품] | T19: 필터
A20: daiso1029135 | D20: 0 | E20: 1029135/키재기줄자2M | F20: 단종 | G20: 다이소 | J20: 15*12*3.5cm | K20: HENAN HUAJIANG INDUSTRY CO., LTD | L20: 무역(수입) | M20: 글로벌소싱부 | Q20: 유통사업부 | R20: 툴스피아,우리물류(회송전) | S20: [상품] | T20: 공구
A21: daiso10341 | B21: 8808739000108 | C21: 28808739103414 | D21: 38808739103411 | E21: 10341/Fix순간접착제(젤형) | F21: 판매중 | G21: 다이소 | H21: 10341 | I21: =VLOOKUP(A:A,[1]기본데이터!$B:$E,4,0) -> FIX순간접착제(젤형) | J21: 젤형 3g | K21: GS코퍼레이션 | L21: 국내사입 | M21: 물류운영부 | N21: 박유정 | Q21: 유통사업부 | R21: 툴스피아,우리물류(회송전) | S21: [상품] | T21: 접착
A22: daiso10342 | B22: 8808739000108 | C22: 28808739103421 | D22: 38808739103428 | E22: 10342/Fix순간접착제(펜형) | F22: 판매중 | G22: 다이소 | H22: 10342 | I22: =VLOOKUP(A:A,[1]기본데이터!$B:$E,4,0) -> FIX순간접착제(펜형) | J22: 펜형 3g | K22: (주)크록스 | Q22: 유통사업부 | R22: 툴스피아,우리물류(회송전) | S22: [상품] | T22: 접착
A23: daiso1034744 | B23: 8819910347448 | C23: 28819910347442 | D23: 38819910347449 | E23: 1034744/회색 실란트 300ml | F23: 판매중 | G23: 다이소 | H23: 1034744 | I23: =VLOOKUP(A:A,[1]기본데이터!$B:$E,4,0) -> 회색 실란트 300ml | K23: 주식회사 탑씰 | L23: 국내사입 | M23: 물류운영부 | N23: 박유정 | Q23: 유통사업부 | R23: 툴스피아,우리물류(회송전) | S23: [상품] | T23: 접착
A24: daiso1034749 | B24: 8819910347493 | C24: 28819910347497 | D24: 38819910347494 | E24: 1034749/백색 실란트 300ml | F24: 판매중 | G24: 다이소 | H24: 1034749 | I24: =VLOOKUP(A:A,[1]기본데이터!$B:$E,4,0) -> 백색 실란트 300ml | K24: 주식회사 탑씰 | L24: 국내사입 | M24: 물류운영부 | N24: 박유정 | Q24: 유통사업부 | R24: 툴스피아,우리물류(회송전) | S24: [상품] | T24: 접착
A25: daiso1034750 | B25: 8819910347509 | C25: 28819910347503 | D25: 38819910347500 | E25: 1034750/투명 실란트 300ml | F25: 판매중 | G25: 다이소 | H25: 1034750 | I25: =VLOOKUP(A:A,[1]기본데이터!$B:$E,4,0) -> 투명 실란트 300ml | K25: 주식회사 탑씰 | L25: 국내사입 | M25: 물류운영부 | N25: 박유정 | Q25: 유통사업부 | R25: 툴스피아,우리물류(회송전) | S25: [상품] | T25: 접착
A26: daiso1036955 | B26: 8819910369556 | C26: 28819910369550 | D26: 38819910369557 | E26: 1036955/숏샤워기헤드 | F26: 판매중 | G26: 다이소 | H26: 1036955 | I26: =VLOOKUP(A:A,[1]기본데이터!$B:$E,4,0) -> 숏샤워기헤드 | J26: 60*80*135mm | K26: NINGBO SMARTLIFE HOURSEWARE PRODUCTS CO., LTD | L26: 무역(수입) | M26: 글로벌소싱부 | Q26: 유통사업부 | R26: 툴스피아,우리물류(회송전) | S26: [상품] | T26: 필터
A27: daiso1038018 | B27: 8819910380186 | C27: 28819910380180 | D27: 38819910380187 | E27: 1038018/세면대필터세트(리필2개입포함) | F27: 판매중 | G27: 다이소 | H27: 1038018 | I27: =VLOOKUP(A:A,[1]기본데이터!$B:$E,4,0) -> 세면대필터세트(리필2개입) | J27: 2p | K27: NINGBO ZEXIN SANITARY WARE CO., LTD | L27: 무역(수입) | M27: 글로벌소싱부 | Q27: 유통사업부 | R27: 툴스피아,우리물류(회송전) | S27: [상품] | T27: 수전
A28: daiso1038019 | B28: 8819910380193 | C28: 28819910380197 | D28: 38819910380194 | E28: 1038019/세면대필터리필(4개입) | F28: 판매중 | G28: 다이소 | H28: 1038019 | I28: =VLOOKUP(A:A,[1]기본데이터!$B:$E,4,0) -> 세면대필터리필(4개입) | J28: 4p | K28: 외주포장 | Q28: 유통사업부 | R28: 툴스피아,우리물류(회송전) | S28: [상품] | T28: 필터
A29: daiso1038160 | B29: 8819910381602 | C29: 28819910381606 | D29: 38819910381603 | E29: 1038160/홈실리콘마미씰(회색) | F29: 판매중 | G29: 다이소 | H29: 1038160 | I29: =VLOOKUP(A:A,[1]기본데이터!$B:$E,4,0) -> 홈실리콘마미씰(회색) | J29: 80ml(회색) | K29: 주식회사 탑씰 | L29: 국내사입 | M29: 물류운영부 | N29: 박유정 | Q29: 유통사업부 | R29: 툴스피아,우리물류(회송전) | S29: [상품] | T29: 접착
A30: daiso1038291 | B30: 8819910382913 | C30: 28819910382917 | D30: 38808739574846 | E30: 1038291/다용도 청소분사기세트 | F30: 단종 | G30: 다이소 | H30: 1038291 | K30: NINGBO SOURCE E-BUSINESS CO., LTD | L30: 무역(수입) | M30: 글로벌소싱부 | Q30: 유통사업부 | R30: 툴스피아,우리물류(회송전) | S30: [상품] | T30: 수전
A31: daiso1038730 | B31: 8819910387307 | C31: 28819910387301 | D31: 38819910387308 | E31: 1038730/오토락줄자 7.5M | F31: 판매중 | G31: 다이소 | H31: 1038730 | I31: =VLOOKUP(A:A,[1]기본데이터!$B:$E,4,0) -> 오토락줄자(25 mm*7.5 m) | J31: 7.5M | K31: HENAN FOCUS IMPORT AND EXPORT TRADING CO., LTD | L31: 무역(수입) | M31: 글로벌소싱부 | Q31: 유통사업부 | R31: 툴스피아,우리물류(회송전) | S31: [상품] | T31: 공구
A32: daiso1038731 | B32: 8819910387314 | C32: 28819910387318 | D32: 38819910387315 | E32: 1038731/열쇠고리줄자(6mm*2mm) | F32: 판매중 | G32: 다이소 | H32: 1038731 | I32: =VLOOKUP(A:A,[1]기본데이터!$B:$E,4,0) -> 열쇠고리줄자(6 mm*2 m) | J32: 6mm*2mm | K32: HENAN FOCUS IMPORT AND EXPORT TRADING CO., LTD | L32: 무역(수입) | M32: 글로벌소싱부 | Q32: 유통사업부 | R32: 툴스피아,우리물류(회송전) | S32: [상품] | T32: 공구
A33: daiso1041773 | D33: 38819910417739 | E33: 1041773/녹제거제(20g) | F33: 단종 | G33: 다이소 | H33: 1041773 | K33: GS코퍼레이션 | L33: 국내사입 | M33: 물류운영부 | N33: 박유정 | Q33: 유통사업부 | R33: 툴스피아,우리물류(회송전) | S33: [상품] | T33: 케미
A34: daiso1043287 | B34: 0409910432879 | C34: 20409910432873 | D34: 30409910432870 | E34: 1043287/솔릭스픽스(목재용) | F34: 판매중 | G34: 다이소 | H34: 1043287 | I34: =VLOOKUP(A:A,[1]기본데이터!$B:$E,4,0) -> 솔릭스픽스(목재용) | J34: 목재용 20g | K34: GS코퍼레이션 | L34: 국내사입 | M34: 물류운영부 | N34: 박유정 | Q34: 유통사업부 | R34: 툴스피아,우리물류(회송전) | S34: [상품] | T34: 접착
A35: daiso1043838 | D35: 30409910438384 | E35: 1043838/일자브러쉬(40mm) | F35: 단종 | G35: 다이소 | H35: 1043838 | J35: 40mm | K35: ROLLINGDOG (NINGBO) IMP AND EXP CO., LTD | L35: 무역(수입) | M35: 글로벌소싱부 | Q35: 유통사업부 | R35: 툴스피아,우리물류(회송전) | S35: [상품] | T35: 잡화
A36: daiso1043839 | D36: 30409910438391 | E36: 1043839/앵글브러쉬(40mm) | F36: 단종 | G36: 다이소 | H36: 1043839 | J36: 40mm | K36: ROLLINGDOG (NINGBO) IMP AND EXP CO., LTD | L36: 무역(수입) | M36: 글로벌소싱부 | Q36: 유통사업부 | R36: 툴스피아,우리물류(회송전) | S36: [상품] | T36: 잡화
A37: daiso1043840 | D37: 30409910438407 | E37: 1043840/일자브러쉬(65mm) | F37: 단종 | G37: 다이소 | H37: 1043840 | J37: 65mm | K37: ROLLINGDOG (NINGBO) IMP AND EXP CO., LTD | L37: 무역(수입) | M37: 글로벌소싱부 | Q37: 유통사업부 | R37: 툴스피아,우리물류(회송전) | S37: [상품] | T37: 잡화
A38: daiso1043841 | D38: 30409910438414 | E38: 1043841/앵글브러쉬(65mm) | F38: 단종 | G38: 다이소 | H38: 1043841 | J38: 40mm | K38: ROLLINGDOG (NINGBO) IMP AND EXP CO., LTD | L38: 무역(수입) | M38: 글로벌소싱부 | Q38: 유통사업부 | R38: 툴스피아,우리물류(회송전) | S38: [상품] | T38: 잡화
A39: daiso1044098 | B39: 0409910440980 | C39: 20409910440984 | D39: 30409910440981 | E39: 1044098/자바라 가스터보라이터 | F39: 판매중 | G39: 다이소 | H39: 1044098 | I39: =VLOOKUP(A:A,[1]기본데이터!$B:$E,4,0) -> 자바라 가스터보라이터 | K39: YUYAO HAPPY LIGHT INDUSTRIAL PRODUCTS CO., LTD | L39: 무역(수입) | M39: 글로벌소싱부 | Q39: 유통사업부 | R39: 툴스피아,우리물류(회송전) | S39: [상품] | T39: 공구
A40: daiso1045580 | B40: 0409910455809 | C40: 20409910455803 | D40: 30409910455800 | E40: 1045580/미니톱(당김방식) | F40: 판매중 | G40: 다이소 | H40: 1045580 | I40: =VLOOKUP(A:A,[1]기본데이터!$B:$E,4,0) -> 미니톱(당김방식) | J40: (당김방식) | K40: YONGKANG HUARUI IMP AND EXP CO., LTD | L40: 무역(수입) | M40: 글로벌소싱부 | Q40: 유통사업부 | R40: 툴스피아,우리물류(회송전) | S40: [상품] | T40: 공구
...
